<?xml version="1.0" ?>
<!-- =================================================================================== -->
<!-- |    This document was autogenerated by xacro from /home/robot/catkin_ws/src/wpr2/wpr2_description/urdf/wpr2.urdf.xacro | -->
<!-- |    EDITING THIS FILE BY HAND IS NOT RECOMMENDED                                 | -->
<!-- =================================================================================== -->
<robot name="wpr2">
    <material name="black">
        <color rgba="0 0 0 1" />
    </material>
    <!-- base_footprint -->
    <link name="base_footprint">
        <visual>
            <origin rpy="0 0 0" xyz="0 0 0" />
            <geometry>
                <box size="0.001 0.001 0.001" />
            </geometry>
            <material name="TransparentGreen" />
        </visual>
    </link>
    <joint name="base_joint" type="fixed">
        <origin rpy="0 0 0" xyz="0 0 0.02" />
        <parent link="base_footprint" />
        <child link="base_link" />
    </joint>
    <!-- base_link -->
    <link name="base_link">
        <visual>
            <geometry>
                <mesh filename="package://wpr2_description/meshes/base.dae" scale="1 1 1" />
            </geometry>
            <origin rpy="0 0 0" xyz="0.0 0.0 0.13" />
        </visual>
        <visual>
            <geometry>
                <box size="0.02 0.32 0.2" />
            </geometry>
            <origin rpy="0 0 0" xyz="-0.13 0.0 1.0" />
            <material name="black" />
        </visual>
        <!-- 底盘碰撞体 -->
        <collision>
            <origin rpy="0 0 0" xyz="0.005 0 0.07" />
            <geometry>
                <box size="0.57 0.46 0.12" />
            </geometry>
        </collision>
        <!-- 上舱盖 -->
        <collision>
            <origin rpy="0 0 0" xyz="-0.03 0 0.20" />
            <geometry>
                <box size="0.50 0.37 0.04" />
            </geometry>
        </collision>
        <!-- 立柱 -->
        <collision>
            <origin rpy="0 0 0" xyz="-0.07 0 0.68" />
            <geometry>
                <box size="0.10 0.20 0.90" />
            </geometry>
        </collision>
        <!-- 屏幕 -->
        <collision>
            <origin rpy="0 0 0" xyz="-0.13 0.0 1.0" />
            <geometry>
                <box size="0.02 0.32 0.2" />
            </geometry>
        </collision>
        <inertial>
            <mass value="20" />
            <inertia ixx="10" ixy="0.0" ixz="0.0" iyy="10" iyz="0.0" izz="10" />
            <origin xyz="0 0 0" rpy="0 0 0" />
        </inertial>
    </link>
    <link name="front_left_wheel_link">
        <visual>
            <origin rpy="1.570796327 0 0" xyz="0.0 0.06 0.0" />
            <geometry>
                <mesh filename="package://wpr2_description/meshes/mecanum_a.dae" scale="1 1 1" />
            </geometry>
        </visual>
        <collision>
            <origin rpy="1.570796327 0 0" xyz="0 0.029 0" />
            <geometry>
                <cylinder length="0.058" radius="0.001" />
            </geometry>
        </collision>
        <inertial>
            <mass value="0.00001" />
            <inertia ixx="0.1" ixy="0.0" ixz="0.0" iyy="0.1" iyz="0.0" izz="0.1" />
            <origin xyz="0 0 0" rpy="0 0 0" />
        </inertial>
    </link>
    <joint name="front_left_wheel_joint" type="continuous">
        <parent link="base_link" />
        <child link="front_left_wheel_link" />
        <origin rpy="0 0.0 0.0" xyz="0.1975   0.185  0.029" />
        <axis xyz="0 1 0" />
    </joint>
    <transmission name="front_left_transmission">
        <type>transmission_interface/SimpleTransmission</type>
        <joint name="front_left_wheel_joint">
            <hardwareInterface>hardware_interface/PositionJointInterface</hardwareInterface>
        </joint>
        <actuator name="front_left_motor">
            <hardwareInterface>PositionJointInterface</hardwareInterface>
            <mechanicalReduction>1</mechanicalReduction>
        </actuator>
    </transmission>
    <link name="front_right_wheel_link">
        <visual>
            <origin rpy="1.570796327 0 0" xyz="0.0 0.06 0.0" />
            <geometry>
                <mesh filename="package://wpr2_description/meshes/mecanum_b.dae" scale="1 1 1" />
            </geometry>
        </visual>
        <collision>
            <origin rpy="1.570796327 0 0" xyz="0 0.029 0" />
            <geometry>
                <cylinder length="0.058" radius="0.001" />
            </geometry>
        </collision>
        <inertial>
            <mass value="0.00001" />
            <inertia ixx="0.1" ixy="0.0" ixz="0.0" iyy="0.1" iyz="0.0" izz="0.1" />
            <origin xyz="0 0 0" rpy="0 0 0" />
        </inertial>
    </link>
    <joint name="front_right_wheel_joint" type="continuous">
        <parent link="base_link" />
        <child link="front_right_wheel_link" />
        <origin rpy="3.141592653589793 0.0 0.0" xyz="0.1975   -0.185  0.029" />
        <axis xyz="0 1 0" />
    </joint>
    <transmission name="front_right_transmission">
        <type>transmission_interface/SimpleTransmission</type>
        <joint name="front_right_wheel_joint">
            <hardwareInterface>hardware_interface/PositionJointInterface</hardwareInterface>
        </joint>
        <actuator name="front_right_motor">
            <hardwareInterface>PositionJointInterface</hardwareInterface>
            <mechanicalReduction>1</mechanicalReduction>
        </actuator>
    </transmission>
    <link name="back_right_wheel_link">
        <visual>
            <origin rpy="1.570796327 0 0" xyz="0.0 0.06 0.0" />
            <geometry>
                <mesh filename="package://wpr2_description/meshes/mecanum_a.dae" scale="1 1 1" />
            </geometry>
        </visual>
        <collision>
            <origin rpy="1.570796327 0 0" xyz="0 0.029 0" />
            <geometry>
                <cylinder length="0.058" radius="0.001" />
            </geometry>
        </collision>
        <inertial>
            <mass value="0.00001" />
            <inertia ixx="0.1" ixy="0.0" ixz="0.0" iyy="0.1" iyz="0.0" izz="0.1" />
            <origin xyz="0 0 0" rpy="0 0 0" />
        </inertial>
    </link>
    <joint name="back_right_wheel_joint" type="continuous">
        <parent link="base_link" />
        <child link="back_right_wheel_link" />
        <origin rpy="3.141592653589793 0.0 0.0" xyz="-0.1975   -0.185  0.029" />
        <axis xyz="0 1 0" />
    </joint>
    <transmission name="back_right_transmission">
        <type>transmission_interface/SimpleTransmission</type>
        <joint name="back_right_wheel_joint">
            <hardwareInterface>hardware_interface/PositionJointInterface</hardwareInterface>
        </joint>
        <actuator name="back_right_motor">
            <hardwareInterface>PositionJointInterface</hardwareInterface>
            <mechanicalReduction>1</mechanicalReduction>
        </actuator>
    </transmission>
    <link name="back_left_wheel_link">
        <visual>
            <origin rpy="1.570796327 0 0" xyz="0.0 0.06 0.0" />
            <geometry>
                <mesh filename="package://wpr2_description/meshes/mecanum_b.dae" scale="1 1 1" />
            </geometry>
        </visual>
        <collision>
            <origin rpy="1.570796327 0 0" xyz="0 0.029 0" />
            <geometry>
                <cylinder length="0.058" radius="0.001" />
            </geometry>
        </collision>
        <inertial>
            <mass value="0.00001" />
            <inertia ixx="0.1" ixy="0.0" ixz="0.0" iyy="0.1" iyz="0.0" izz="0.1" />
            <origin xyz="0 0 0" rpy="0 0 0" />
        </inertial>
    </link>
    <joint name="back_left_wheel_joint" type="continuous">
        <parent link="base_link" />
        <child link="back_left_wheel_link" />
        <origin rpy="0 0.0 0.0" xyz="-0.1975   0.185  0.029" />
        <axis xyz="0 1 0" />
    </joint>
    <transmission name="back_left_transmission">
        <type>transmission_interface/SimpleTransmission</type>
        <joint name="back_left_wheel_joint">
            <hardwareInterface>hardware_interface/PositionJointInterface</hardwareInterface>
        </joint>
        <actuator name="back_left_motor">
            <hardwareInterface>PositionJointInterface</hardwareInterface>
            <mechanicalReduction>1</mechanicalReduction>
        </actuator>
    </transmission>
    <link name="front_left_foot_link">
        <visual>
            <origin rpy="0 0 0" xyz="0.0 0.0 0.0" />
            <geometry>
                <box size="0.001 0.001 0.001" />
            </geometry>
        </visual>
        <collision>
            <origin rpy="0 0 0" xyz="0 0 0" />
            <geometry>
                <cylinder length="0.01" radius="0.05" />
            </geometry>
        </collision>
        <inertial>
            <mass value="0.1" />
            <inertia ixx="1" ixy="0.0" ixz="0.0" iyy="1" iyz="0.0" izz="1" />
            <origin xyz="0 0 0" rpy="0 0 0" />
        </inertial>
    </link>
    <joint name="front_left_foot_joint" type="fixed">
        <parent link="base_link" />
        <child link="front_left_foot_link" />
        <origin rpy="1.57 0.0 0.0" xyz="0.1975   0.24666666666666667  0.029" />
    </joint>
    <link name="front_right_foot_link">
        <visual>
            <origin rpy="0 0 0" xyz="0.0 0.0 0.0" />
            <geometry>
                <box size="0.001 0.001 0.001" />
            </geometry>
        </visual>
        <collision>
            <origin rpy="0 0 0" xyz="0 0 0" />
            <geometry>
                <cylinder length="0.01" radius="0.05" />
            </geometry>
        </collision>
        <inertial>
            <mass value="0.1" />
            <inertia ixx="1" ixy="0.0" ixz="0.0" iyy="1" iyz="0.0" izz="1" />
            <origin xyz="0 0 0" rpy="0 0 0" />
        </inertial>
    </link>
    <joint name="front_right_foot_joint" type="fixed">
        <parent link="base_link" />
        <child link="front_right_foot_link" />
        <origin rpy="1.57 0.0 0.0" xyz="0.1975   -0.24666666666666667  0.029" />
    </joint>
    <link name="back_right_foot_link">
        <visual>
            <origin rpy="0 0 0" xyz="0.0 0.0 0.0" />
            <geometry>
                <box size="0.001 0.001 0.001" />
            </geometry>
        </visual>
        <collision>
            <origin rpy="0 0 0" xyz="0 0 0" />
            <geometry>
                <cylinder length="0.01" radius="0.05" />
            </geometry>
        </collision>
        <inertial>
            <mass value="0.1" />
            <inertia ixx="1" ixy="0.0" ixz="0.0" iyy="1" iyz="0.0" izz="1" />
            <origin xyz="0 0 0" rpy="0 0 0" />
        </inertial>
    </link>
    <joint name="back_right_foot_joint" type="fixed">
        <parent link="base_link" />
        <child link="back_right_foot_link" />
        <origin rpy="1.57 0.0 0.0" xyz="-0.1975   -0.24666666666666667  0.029" />
    </joint>
    <link name="back_left_foot_link">
        <visual>
            <origin rpy="0 0 0" xyz="0.0 0.0 0.0" />
            <geometry>
                <box size="0.001 0.001 0.001" />
            </geometry>
        </visual>
        <collision>
            <origin rpy="0 0 0" xyz="0 0 0" />
            <geometry>
                <cylinder length="0.01" radius="0.05" />
            </geometry>
        </collision>
        <inertial>
            <mass value="0.1" />
            <inertia ixx="1" ixy="0.0" ixz="0.0" iyy="1" iyz="0.0" izz="1" />
            <origin xyz="0 0 0" rpy="0 0 0" />
        </inertial>
    </link>
    <joint name="back_left_foot_joint" type="fixed">
        <parent link="base_link" />
        <child link="back_left_foot_link" />
        <origin rpy="1.57 0.0 0.0" xyz="-0.1975   0.24666666666666667  0.029" />
    </joint>
    <!-- Lidar -->
    <link name="laser">
        <visual>
            <geometry>
                <cylinder length="0.001" radius="0.001" />
            </geometry>
            <origin rpy="0 0 0" xyz="0 0 0" />
        </visual>
    </link>
    <joint name="laser_joint" type="fixed">
        <origin rpy="0 0 3.1415926" xyz="0 0 0.16" />
        <parent link="base_link" />
        <child link="laser" />
    </joint>
    <!-- Gazebo plugin for RpLidar C1 -->
    <gazebo reference="laser">
        <sensor name="rplidar_sensor" type="ray">
            <pose>0 0 0.06 0 0 0</pose>
            <visualize>false</visualize>
            <update_rate>10</update_rate>
            <ray>
                <scan>
                    <horizontal>
                        <samples>720</samples>
                        <resolution>1</resolution>
                        <min_angle>-3.14159265</min_angle>
                        <max_angle>3.14159265</max_angle>
                    </horizontal>
                </scan>
                <range>
                    <min>0.02</min>
                    <max>10.0</max>
                    <resolution>0.01</resolution>
                </range>
                <!-- <noise>
          <type>gaussian</type>
          <mean>0.0</mean>
          <stddev>0.01</stddev>
        </noise> -->
            </ray>
            <plugin filename="libgazebo_ros_laser.so" name="rplidar_ros_controller">
                <topicName>scan_raw</topicName>
                <frameName>laser</frameName>
            </plugin>
        </sensor>
        <plugin name="gazebo_ros_control" filename="libgazebo_ros_control.so">
            <robotNamespace>/</robotNamespace>
        </plugin>
    </gazebo>
    <link name="chest_link">
        <visual>
            <geometry>
                <mesh filename="package://wpr2_description/meshes/chest.dae" scale=" 1 1 1 " />
            </geometry>
            <origin rpy="0 0 0" xyz="0.015 0.0 0.01" />
        </visual>
        <collision>
            <origin rpy="0 0 0" xyz="0.04 0 -0.01" />
            <geometry>
                <box size="0.1 0.22 0.15" />
            </geometry>
        </collision>
        <inertial>
            <mass value="1" />
            <inertia ixx="0.1" ixy="0.0" ixz="0.0" iyy="0.1" iyz="0.0" izz="0.01" />
            <origin xyz="0 0 0" rpy="0 0 0" />
        </inertial>
    </link>
    <joint name="chest_height" type="prismatic">
        <parent link="base_link" />
        <child link="chest_link" />
        <limit effort="1000.0" lower="0" upper="0.7" velocity="0.5" />
        <dynamics damping="0.0" friction="0.0" />
        <origin rpy="0 0 0" xyz="0.0 0 0.4" />
        <axis xyz="0 0 1" />
    </joint>
    <transmission name="chest_height_transmission">
        <type>transmission_interface/SimpleTransmission</type>
        <joint name="chest_height">
            <hardwareInterface>hardware_interface/PositionJointInterface</hardwareInterface>
        </joint>
        <actuator name="chest_height_motor">
            <hardwareInterface>PositionJointInterface</hardwareInterface>
            <mechanicalReduction>1</mechanicalReduction>
        </actuator>
    </transmission>
    <!-- Camera -->
    <link name="femto_base">
        <visual>
            <origin rpy="0 0 0" xyz="0 0 0" />
            <geometry>
                <!-- <box size=".1 .25 .07"/> -->
                <box size="0 0 0" />
            </geometry>
        </visual>
        <inertial>
            <mass value="0.1" />
            <inertia ixx="0.1" ixy="0.0" ixz="0.0" iyy="0.1" iyz="0.0" izz="0.01" />
        </inertial>
    </link>
    <joint name="femto_height" type="prismatic">
        <parent link="chest_link" />
        <child link="femto_base" />
        <limit effort="1000.0" lower="0" upper="0.1" velocity="0.5" />
        <origin rpy="0 -1.5707963 0" xyz="0.05 0 0" />
    </joint>
    <transmission name="femto_height_transmission">
        <type>transmission_interface/SimpleTransmission</type>
        <joint name="femto_height">
            <hardwareInterface>hardware_interface/PositionJointInterface</hardwareInterface>
        </joint>
        <actuator name="femto_height_motor">
            <hardwareInterface>PositionJointInterface</hardwareInterface>
            <mechanicalReduction>1</mechanicalReduction>
        </actuator>
    </transmission>
    <link name="camera_link">
        <visual>
            <origin rpy="0 0 0" xyz="0 0 0" />
            <geometry>
                <mesh filename="package://wpr2_description/meshes/femto_bolt.dae" scale="1 1 1" />
            </geometry>
        </visual>
        <collision>
            <origin rpy="0 0 0" xyz="-0.015 0 0" />
            <geometry>
                <box size="0.05 0.1 0.04" />
            </geometry>
        </collision>
        <inertial>
            <mass value="1" />
            <inertia ixx="0.1" ixy="0.0" ixz="0.0" iyy="0.1" iyz="0.0" izz="0.01" />
            <origin xyz="0 0 0" rpy="0 0 0" />
        </inertial>
    </link>
    <joint name="femto_pitch" type="revolute">
        <axis xyz="0 -1 0" />
        <limit effort="1000.0" lower="-1.57" upper="1.57" velocity="0.5" />
        <origin rpy="0 1.57 0" xyz="0 0 0" />
        <parent link="femto_base" />
        <child link="camera_link" />
    </joint>
    <transmission name="femto_pitch_transmission">
        <type>transmission_interface/SimpleTransmission</type>
        <joint name="femto_pitch">
            <hardwareInterface>hardware_interface/PositionJointInterface</hardwareInterface>
        </joint>
        <actuator name="femto_pitch_motor">
            <hardwareInterface>PositionJointInterface</hardwareInterface>
            <mechanicalReduction>1</mechanicalReduction>
        </actuator>
    </transmission>
    <!-- joint 0 -->
    <link name="left_link_0" />
    <joint name="left_joint_0" type="fixed">
        <parent link="chest_link" />
        <child link="left_link_0" />
        <origin rpy="0 3.141592653589793 0" xyz="0.035 0.18 0.0" />
    </joint>
    <!-- joint 1 -->
    <link name="left_link_1">
        <visual>
            <geometry>
                <mesh filename="package://wpr2_description/meshes/arm/arm_link_1.dae" scale="1 1 1" />
            </geometry>
            <origin rpy="-1.5707963267948966 0 1.5707963267948966" xyz="0 -0.07 0" />
        </visual>
        <collision>
            <origin rpy="0 1.5707963267948966 0" xyz="0.09 0 0" />
            <geometry>
                <cylinder length="0.07" radius="0.041" />
            </geometry>
        </collision>
        <inertial>
            <mass value="0.1" />
            <inertia ixx="0.1" ixy="0.0" ixz="0.0" iyy="0.1" iyz="0.0" izz="0.01" />
            <origin xyz="0 0 0" rpy="0 0 0" />
        </inertial>
    </link>
    <joint name="left_joint_1" type="continuous">
        <parent link="left_link_0" />
        <child link="left_link_1" />
        <origin rpy="0 0 0" xyz="0.0 0 0.0" />
        <axis xyz="0 1 0" />
    </joint>
    <transmission name="left_joint_1_transmission">
        <type>transmission_interface/SimpleTransmission</type>
        <joint name="left_joint_1">
            <hardwareInterface>hardware_interface/PositionJointInterface</hardwareInterface>
        </joint>
        <actuator name="left_joint_1_motor">
            <hardwareInterface>PositionJointInterface</hardwareInterface>
            <mechanicalReduction>1</mechanicalReduction>
        </actuator>
    </transmission>
    <!-- joint 2 -->
    <link name="left_link_2">
        <visual>
            <geometry>
                <mesh filename="package://wpr2_description/meshes/arm/arm_link_2.dae" scale="1 1 1" />
            </geometry>
            <origin rpy="3.141592653589793 3.141592653589793 0" xyz="0 0 0" />
        </visual>
        <collision>
            <origin rpy="-1.5707963267948966 0 0" xyz="0 0.05 0 " />
            <geometry>
                <cylinder length="0.18" radius="0.041" />
            </geometry>
        </collision>
        <inertial>
            <mass value="0.1" />
            <inertia ixx="0.1" ixy="0.0" ixz="0.0" iyy="0.1" iyz="0.0" izz="0.01" />
            <origin xyz="0 0 0" rpy="0 0 0" />
        </inertial>
    </link>
    <joint name="left_joint_2" type="continuous">
        <parent link="left_link_1" />
        <child link="left_link_2" />
        <origin rpy="0 3.141592653589793 0" xyz="0 0 0 " />
        <axis xyz="1 0 0" />
    </joint>
    <transmission name="left_joint_2_transmission">
        <type>transmission_interface/SimpleTransmission</type>
        <joint name="left_joint_2">
            <hardwareInterface>hardware_interface/PositionJointInterface</hardwareInterface>
        </joint>
        <actuator name="left_joint_2_motor">
            <hardwareInterface>PositionJointInterface</hardwareInterface>
            <mechanicalReduction>1</mechanicalReduction>
        </actuator>
    </transmission>
    <!-- joint 3 -->
    <link name="left_link_3">
        <visual>
            <geometry>
                <mesh filename="package://wpr2_description/meshes/arm/arm_link_3.dae" scale="1 1 1" />
            </geometry>
            <origin rpy="-1.5707963267948966 0 -1.5707963267948966" xyz="0 0.19 0" />
        </visual>
        <collision>
            <origin rpy="0 0 0" xyz="0 0.19 0" />
            <geometry>
                <cylinder length="0.12" radius="0.041" />
            </geometry>
        </collision>
        <inertial>
            <mass value="0.1" />
            <inertia ixx="0.1" ixy="0.0" ixz="0.0" iyy="0.1" iyz="0.0" izz="0.01" />
            <origin xyz="0 0 0" rpy="0 0 0" />
        </inertial>
    </link>
    <joint name="left_joint_3" type="continuous">
        <parent link="left_link_2" />
        <child link="left_link_3" />
        <origin rpy="0 0 0" xyz="0 0 0 " />
        <axis xyz="0 1 0" />
    </joint>
    <transmission name="left_joint_3_transmission">
        <type>transmission_interface/SimpleTransmission</type>
        <joint name="left_joint_3">
            <hardwareInterface>hardware_interface/PositionJointInterface</hardwareInterface>
        </joint>
        <actuator name="left_joint_3_motor">
            <hardwareInterface>PositionJointInterface</hardwareInterface>
            <mechanicalReduction>1</mechanicalReduction>
        </actuator>
    </transmission>
    <!-- joint 4 -->
    <link name="left_link_4">
        <visual>
            <geometry>
                <mesh filename="package://wpr2_description/meshes/arm/arm_link_4.dae" scale="1 1 1" />
            </geometry>
            <origin rpy="1.5707963267948966 1.5707963267948966 0" xyz="0 0 0.051" />
        </visual>
        <collision>
            <origin rpy="1.5707963267948966  0 0" xyz="0 0.09 0" />
            <geometry>
                <cylinder length="0.07" radius="0.041" />
            </geometry>
        </collision>
        <inertial>
            <mass value="0.1" />
            <inertia ixx="0.1" ixy="0.0" ixz="0.0" iyy="0.1" iyz="0.0" izz="0.01" />
            <origin xyz="0 0 0" rpy="0 0 0" />
        </inertial>
    </link>
    <joint name="left_joint_4" type="continuous">
        <parent link="left_link_3" />
        <child link="left_link_4" />
        <origin rpy="0 0 0" xyz="0 0.19 0" />
        <axis xyz="0 0 1" />
    </joint>
    <transmission name="left_joint_4_transmission">
        <type>transmission_interface/SimpleTransmission</type>
        <joint name="left_joint_4">
            <hardwareInterface>hardware_interface/PositionJointInterface</hardwareInterface>
        </joint>
        <actuator name="left_joint_4_motor">
            <hardwareInterface>PositionJointInterface</hardwareInterface>
            <mechanicalReduction>1</mechanicalReduction>
        </actuator>
    </transmission>
    <!-- joint 5 -->
    <link name="left_link_5">
        <visual>
            <geometry>
                <mesh filename="package://wpr2_description/meshes/arm/arm_link_5.dae" scale="1 1 1" />
            </geometry>
            <origin rpy="-1.5707963267948966 0 -1.5707963267948966" xyz="0 0 0" />
        </visual>
        <collision>
            <origin rpy="0 0 0" xyz="0 0 0" />
            <geometry>
                <cylinder length="0.12" radius="0.041" />
            </geometry>
        </collision>
        <inertial>
            <mass value="0.1" />
            <inertia ixx="0.1" ixy="0.0" ixz="0.0" iyy="0.1" iyz="0.0" izz="0.01" />
            <origin xyz="0 0 0" rpy="0 0 0" />
        </inertial>
    </link>
    <joint name="left_joint_5" type="continuous">
        <parent link="left_link_4" />
        <child link="left_link_5" />
        <origin rpy="0 1.5707963267948966 0" xyz="0 0.17 0" />
        <axis xyz="0 1 0" />
    </joint>
    <transmission name="left_joint_5_transmission">
        <type>transmission_interface/SimpleTransmission</type>
        <joint name="left_joint_5">
            <hardwareInterface>hardware_interface/PositionJointInterface</hardwareInterface>
        </joint>
        <actuator name="left_joint_5_motor">
            <hardwareInterface>PositionJointInterface</hardwareInterface>
            <mechanicalReduction>1</mechanicalReduction>
        </actuator>
    </transmission>
    <!-- joint 6 palm -->
    <link name="left_link_6">
        <visual>
            <geometry>
                <mesh filename="package://wpr2_description/meshes/arm/arm_link_palm.dae" scale="1 1 1" />
            </geometry>
            <origin rpy="-1.5707963267948966 1.5707963267948966  0" xyz="0 0 0.05" />
        </visual>
        <inertial>
            <mass value="0.1" />
            <inertia ixx="0.1" ixy="0.0" ixz="0.0" iyy="0.1" iyz="0.0" izz="0.01" />
        </inertial>
    </link>
    <joint name="left_joint_6" type="continuous">
        <parent link="left_link_5" />
        <child link="left_link_6" />
        <origin rpy="0 0 0" xyz="0 0 0" />
        <axis xyz="0 0 1" />
    </joint>
    <transmission name="left_joint_6_transmission">
        <type>transmission_interface/SimpleTransmission</type>
        <joint name="left_joint_6">
            <hardwareInterface>hardware_interface/PositionJointInterface</hardwareInterface>
        </joint>
        <actuator name="left_joint_6_motor">
            <hardwareInterface>PositionJointInterface</hardwareInterface>
            <mechanicalReduction>1</mechanicalReduction>
        </actuator>
    </transmission>
    <link name="left_link_finger">
        <visual>
            <geometry>
                <mesh filename="package://wpr2_description/meshes/arm/arm_link_palm.dae" scale="1 1 1" />
            </geometry>
            <origin rpy="-1.5707963267948966 -1.5707963267948966 0" xyz="0 0 -0.05" />
        </visual>
        <inertial>
            <mass value="0.1" />
            <inertia ixx="0.1" ixy="0.0" ixz="0.0" iyy="0.1" iyz="0.0" izz="0.01" />
        </inertial>
    </link>
    <joint name="left_joint_finger" type="fixed">
        <parent link="left_link_6" />
        <child link="left_link_finger" />
        <origin rpy="0 0 0" xyz="0 0 0" />
    </joint>
    <!-- finger 0-->
    <!-- <link name="left_finger_0">
      <visual>
        <geometry>
          <box size="0.02 0.02 0.08"/>
        </geometry>
        <origin rpy="0 0 0" xyz="0 0 -0.04"/>
        <material name="white"/>
      </visual>
    </link>
    <joint name="left_finger_joint" type="prismatic">
      <parent link="left_link_5"/>
      <child link="left_finger_0"/>
      <origin xyz="0 0 -0.325"/>
      <axis xyz="0 1 0"/>
      <limit effort="1000.0" lower="0" upper="0.05" velocity="0.5"/>
    </joint> -->
    <!-- finger 1-->
    <!-- <link name="left_finger_1">
      <visual>
        <geometry>
          <box size="0.02 0.02 0.08"/>
        </geometry>
        <origin rpy="0 0 0" xyz="0 0 -0.04"/>
        <material name="white"/>
      </visual>
    </link>
    <joint name="left_finger_joint_1" type="prismatic">
      <parent link="left_link_5"/>
      <child link="left_finger_1"/>
      <origin xyz="0 0 -0.325"/>
      <axis xyz="0 -1 0"/>
      <limit effort="1000.0" lower="0" upper="0.05" velocity="0.5"/>
      <mimic joint="left_finger_joint" multiplier="1" offset="0"/>
    </joint> -->
    <!-- TCP(Tool Center Point) -->
    <link name="left_tcp_link">
        <inertial>
            <mass value="0.001" />
            <origin rpy="0 0 0" xyz="0 0 0" />
            <inertia ixx="0.0001" ixy="0" ixz="0" iyy="0.0001" iyz="0" izz="0.0001" />
        </inertial>
        <!-- 手爪根部 -->
        <collision>
            <origin rpy="0 0 0" xyz="0.0 -0.13 0.0" />
            <geometry>
                <box size="0.08 0.05 0.1" />
            </geometry>
        </collision>
        <!-- 手指活动范围 -->
        <collision>
            <origin rpy="0 0 0" xyz="0.0 -0.028 0.0" />
            <geometry>
                <box size="0.18 0.15 0.04" />
            </geometry>
        </collision>
    </link>
    <joint name="left_tcp_joint" type="fixed">
        <parent link="left_link_6" />
        <child link="left_tcp_link" />
        <origin rpy="0 0 0" xyz="0 0.2 0" />
    </joint>
    <!-- joint 0 -->
    <link name="right_link_0" />
    <joint name="right_joint_0" type="fixed">
        <parent link="chest_link" />
        <child link="right_link_0" />
        <origin rpy="0 0 3.141592653589793" xyz="0.035 -0.18 0.0" />
    </joint>
    <!-- joint 1 -->
    <link name="right_link_1">
        <visual>
            <geometry>
                <mesh filename="package://wpr2_description/meshes/arm/arm_link_1.dae" scale="1 1 1" />
            </geometry>
            <origin rpy="-1.5707963267948966 0 1.5707963267948966" xyz="0 -0.07 0" />
        </visual>
        <collision>
            <origin rpy="0 1.5707963267948966 0" xyz="0.09 0 0" />
            <geometry>
                <cylinder length="0.07" radius="0.041" />
            </geometry>
        </collision>
        <inertial>
            <mass value="0.1" />
            <inertia ixx="0.1" ixy="0.0" ixz="0.0" iyy="0.1" iyz="0.0" izz="0.01" />
            <origin xyz="0 0 0" rpy="0 0 0" />
        </inertial>
    </link>
    <joint name="right_joint_1" type="continuous">
        <parent link="right_link_0" />
        <child link="right_link_1" />
        <origin rpy="0 0 0" xyz="0.0 0 0.0" />
        <axis xyz="0 1 0" />
    </joint>
    <transmission name="right_joint_1_transmission">
        <type>transmission_interface/SimpleTransmission</type>
        <joint name="right_joint_1">
            <hardwareInterface>hardware_interface/PositionJointInterface</hardwareInterface>
        </joint>
        <actuator name="right_joint_1_motor">
            <hardwareInterface>PositionJointInterface</hardwareInterface>
            <mechanicalReduction>1</mechanicalReduction>
        </actuator>
    </transmission>
    <!-- joint 2 -->
    <link name="right_link_2">
        <visual>
            <geometry>
                <mesh filename="package://wpr2_description/meshes/arm/arm_link_2.dae" scale="1 1 1" />
            </geometry>
            <origin rpy="3.141592653589793 3.141592653589793 0" xyz="0 0 0" />
        </visual>
        <collision>
            <origin rpy="-1.5707963267948966 0 0" xyz="0 0.05 0 " />
            <geometry>
                <cylinder length="0.18" radius="0.041" />
            </geometry>
        </collision>
        <inertial>
            <mass value="0.1" />
            <inertia ixx="0.1" ixy="0.0" ixz="0.0" iyy="0.1" iyz="0.0" izz="0.01" />
            <origin xyz="0 0 0" rpy="0 0 0" />
        </inertial>
    </link>
    <joint name="right_joint_2" type="continuous">
        <parent link="right_link_1" />
        <child link="right_link_2" />
        <origin rpy="0 3.141592653589793 0" xyz="0 0 0 " />
        <axis xyz="1 0 0" />
    </joint>
    <transmission name="right_joint_2_transmission">
        <type>transmission_interface/SimpleTransmission</type>
        <joint name="right_joint_2">
            <hardwareInterface>hardware_interface/PositionJointInterface</hardwareInterface>
        </joint>
        <actuator name="right_joint_2_motor">
            <hardwareInterface>PositionJointInterface</hardwareInterface>
            <mechanicalReduction>1</mechanicalReduction>
        </actuator>
    </transmission>
    <!-- joint 3 -->
    <link name="right_link_3">
        <visual>
            <geometry>
                <mesh filename="package://wpr2_description/meshes/arm/arm_link_3.dae" scale="1 1 1" />
            </geometry>
            <origin rpy="1.5707963267948966 0 -1.5707963267948966" xyz="0 0.19 0" />
        </visual>
        <collision>
            <origin rpy="0 0 0" xyz="0 0.19 0" />
            <geometry>
                <cylinder length="0.12" radius="0.041" />
            </geometry>
        </collision>
        <inertial>
            <mass value="0.1" />
            <inertia ixx="0.1" ixy="0.0" ixz="0.0" iyy="0.1" iyz="0.0" izz="0.01" />
            <origin xyz="0 0 0" rpy="0 0 0" />
        </inertial>
    </link>
    <joint name="right_joint_3" type="continuous">
        <parent link="right_link_2" />
        <child link="right_link_3" />
        <origin rpy="0 0 0" xyz="0 0 0 " />
        <axis xyz="0 1 0" />
    </joint>
    <transmission name="right_joint_3_transmission">
        <type>transmission_interface/SimpleTransmission</type>
        <joint name="right_joint_3">
            <hardwareInterface>hardware_interface/PositionJointInterface</hardwareInterface>
        </joint>
        <actuator name="right_joint_3_motor">
            <hardwareInterface>PositionJointInterface</hardwareInterface>
            <mechanicalReduction>1</mechanicalReduction>
        </actuator>
    </transmission>
    <!-- joint 4 -->
    <link name="right_link_4">
        <visual>
            <geometry>
                <mesh filename="package://wpr2_description/meshes/arm/arm_link_4.dae" scale="1 1 1" />
            </geometry>
            <origin rpy="1.5707963267948966 1.5707963267948966 0" xyz="0 0 0.051" />
        </visual>
        <collision>
            <origin rpy="1.5707963267948966  0 0" xyz="0 0.09 0" />
            <geometry>
                <cylinder length="0.07" radius="0.041" />
            </geometry>
        </collision>
        <inertial>
            <mass value="0.1" />
            <inertia ixx="0.1" ixy="0.0" ixz="0.0" iyy="0.1" iyz="0.0" izz="0.01" />
            <origin xyz="0 0 0" rpy="0 0 0" />
        </inertial>
    </link>
    <joint name="right_joint_4" type="continuous">
        <parent link="right_link_3" />
        <child link="right_link_4" />
        <origin rpy="0 3.141592653589793 0" xyz="0 0.19 0" />
        <axis xyz="0 0 1" />
    </joint>
    <transmission name="right_joint_4_transmission">
        <type>transmission_interface/SimpleTransmission</type>
        <joint name="right_joint_4">
            <hardwareInterface>hardware_interface/PositionJointInterface</hardwareInterface>
        </joint>
        <actuator name="right_joint_4_motor">
            <hardwareInterface>PositionJointInterface</hardwareInterface>
            <mechanicalReduction>1</mechanicalReduction>
        </actuator>
    </transmission>
    <!-- joint 5 -->
    <link name="right_link_5">
        <visual>
            <geometry>
                <mesh filename="package://wpr2_description/meshes/arm/arm_link_5.dae" scale="1 1 1" />
            </geometry>
            <origin rpy="-1.5707963267948966 0 -1.5707963267948966" xyz="0 0 0" />
        </visual>
        <collision>
            <origin rpy="0 0 0" xyz="0 0 0" />
            <geometry>
                <cylinder length="0.12" radius="0.041" />
            </geometry>
        </collision>
        <inertial>
            <mass value="0.1" />
            <inertia ixx="0.1" ixy="0.0" ixz="0.0" iyy="0.1" iyz="0.0" izz="0.01" />
            <origin xyz="0 0 0" rpy="0 0 0" />
        </inertial>
    </link>
    <joint name="right_joint_5" type="continuous">
        <parent link="right_link_4" />
        <child link="right_link_5" />
        <origin rpy="0 -1.5707963267948966 0" xyz="0 0.17 0" />
        <axis xyz="0 1 0" />
    </joint>
    <transmission name="right_joint_5_transmission">
        <type>transmission_interface/SimpleTransmission</type>
        <joint name="right_joint_5">
            <hardwareInterface>hardware_interface/PositionJointInterface</hardwareInterface>
        </joint>
        <actuator name="right_joint_5_motor">
            <hardwareInterface>PositionJointInterface</hardwareInterface>
            <mechanicalReduction>1</mechanicalReduction>
        </actuator>
    </transmission>
    <!-- joint 6 palm -->
    <link name="right_link_6">
        <visual>
            <geometry>
                <mesh filename="package://wpr2_description/meshes/arm/arm_link_palm.dae" scale="1 1 1" />
            </geometry>
            <origin rpy="-1.5707963267948966 1.5707963267948966  0" xyz="0 0 0.05" />
        </visual>
        <inertial>
            <mass value="0.1" />
            <inertia ixx="0.1" ixy="0.0" ixz="0.0" iyy="0.1" iyz="0.0" izz="0.01" />
        </inertial>
    </link>
    <joint name="right_joint_6" type="continuous">
        <parent link="right_link_5" />
        <child link="right_link_6" />
        <origin rpy="0 0 0" xyz="0 0 0" />
        <axis xyz="0 0 1" />
    </joint>
    <transmission name="right_joint_6_transmission">
        <type>transmission_interface/SimpleTransmission</type>
        <joint name="right_joint_6">
            <hardwareInterface>hardware_interface/PositionJointInterface</hardwareInterface>
        </joint>
        <actuator name="right_joint_6_motor">
            <hardwareInterface>PositionJointInterface</hardwareInterface>
            <mechanicalReduction>1</mechanicalReduction>
        </actuator>
    </transmission>
    <link name="right_link_finger">
        <visual>
            <geometry>
                <mesh filename="package://wpr2_description/meshes/arm/arm_link_palm.dae" scale="1 1 1" />
            </geometry>
            <origin rpy="-1.5707963267948966 -1.5707963267948966 0" xyz="0 0 -0.05" />
        </visual>
        <inertial>
            <mass value="0.1" />
            <inertia ixx="0.1" ixy="0.0" ixz="0.0" iyy="0.1" iyz="0.0" izz="0.01" />
        </inertial>
    </link>
    <joint name="right_joint_finger" type="fixed">
        <parent link="right_link_6" />
        <child link="right_link_finger" />
        <origin rpy="0 0 0" xyz="0 0 0" />
    </joint>
    <!-- finger 0-->
    <!-- <link name="right_finger_0">
      <visual>
        <geometry>
          <box size="0.02 0.02 0.08"/>
        </geometry>
        <origin rpy="0 0 0" xyz="0 0 -0.04"/>
        <material name="white"/>
      </visual>
    </link>
    <joint name="right_finger_joint" type="prismatic">
      <parent link="right_link_5"/>
      <child link="right_finger_0"/>
      <origin xyz="0 0 -0.325"/>
      <axis xyz="0 1 0"/>
      <limit effort="1000.0" lower="0" upper="0.05" velocity="0.5"/>
    </joint> -->
    <!-- finger 1-->
    <!-- <link name="right_finger_1">
      <visual>
        <geometry>
          <box size="0.02 0.02 0.08"/>
        </geometry>
        <origin rpy="0 0 0" xyz="0 0 -0.04"/>
        <material name="white"/>
      </visual>
    </link>
    <joint name="right_finger_joint_1" type="prismatic">
      <parent link="right_link_5"/>
      <child link="right_finger_1"/>
      <origin xyz="0 0 -0.325"/>
      <axis xyz="0 -1 0"/>
      <limit effort="1000.0" lower="0" upper="0.05" velocity="0.5"/>
      <mimic joint="right_finger_joint" multiplier="1" offset="0"/>
    </joint> -->
    <!-- TCP(Tool Center Point) -->
    <link name="right_tcp_link">
        <inertial>
            <mass value="0.001" />
            <origin rpy="0 0 0" xyz="0 0 0" />
            <inertia ixx="0.0001" ixy="0" ixz="0" iyy="0.0001" iyz="0" izz="0.0001" />
        </inertial>
        <!-- 手爪根部 -->
        <collision>
            <origin rpy="0 0 0" xyz="0.0 -0.13 0.0" />
            <geometry>
                <box size="0.08 0.05 0.1" />
            </geometry>
        </collision>
        <!-- 手指活动范围 -->
        <collision>
            <origin rpy="0 0 0" xyz="0.0 -0.028 0.0" />
            <geometry>
                <box size="0.18 0.15 0.04" />
            </geometry>
        </collision>
    </link>
    <joint name="right_tcp_joint" type="fixed">
        <parent link="right_link_6" />
        <child link="right_tcp_link" />
        <origin rpy="0 0 0" xyz="0 0.2 0" />
    </joint>
    <gazebo>
        <plugin filename="libgazebo_ros_control.so" name="gazebo_ros_control">
            <robotNamespace>/wpr2</robotNamespace>
            <robotSimType>gazebo_ros_control/DefaultRobotHWSim</robotSimType>
            <legacyModeNS>true</legacyModeNS>
        </plugin>
    </gazebo>
</robot>

